<?xml version="1.0"?>
<robot name="turtlebot3_burger_simple">
  <link name="base_footprint"/>
  <joint name="base_joint" type="fixed">
    <parent link="base_footprint"/>
    <child link="base_link"/>
    <origin xyz="0 0 0.01" rpy="0 0 0"/>
  </joint>
  <link name="base_link">
    <visual>
      <geometry><box size="0.14 0.14 0.07"/></geometry>
      <material name="grey"><color rgba="0.4 0.4 0.4 1"/></material>
    </visual>
  </link>
  <joint name="wheel_left_joint" type="continuous">
    <parent link="base_link"/>
    <child link="wheel_left_link"/>
    <origin xyz="0 0.08 0.023" rpy="-1.57 0 0"/>
    <axis xyz="0 0 1"/>
  </joint>
  <link name="wheel_left_link">
    <visual>
      <geometry><cylinder length="0.018" radius="0.033"/></geometry>
      <material name="dark"><color rgba="0.2 0.2 0.2 1"/></material>
    </visual>
  </link>
  <joint name="wheel_right_joint" type="continuous">
    <parent link="base_link"/>
    <child link="wheel_right_link"/>
    <origin xyz="0 -0.08 0.023" rpy="-1.57 0 0"/>
    <axis xyz="0 0 1"/>
  </joint>
  <link name="wheel_right_link">
    <visual>
      <geometry><cylinder length="0.018" radius="0.033"/></geometry>
      <material name="dark"><color rgba="0.2 0.2 0.2 1"/></material>
    </visual>
  </link>
  <joint name="scan_joint" type="fixed">
    <parent link="base_link"/>
    <child link="base_scan"/>
    <origin xyz="-0.032 0 0.172" rpy="0 0 0"/>
  </joint>
  <link name="base_scan">
    <visual>
      <geometry><cylinder length="0.03" radius="0.04"/></geometry>
      <material name="dark"><color rgba="0.2 0.2 0.2 1"/></material>
    </visual>
  </link>
</robot>
